<?xml version="1.0"?>
<robot name="ur5">

  <!-- =========================== -->
  <!--        Base Link            -->
  <!-- =========================== -->
  <link name="base_link"/>

  <!-- Shoulder Pan Joint -->
  <joint name="shoulder_pan_joint" type="revolute">
    <parent link="base_link"/>
    <child link="shoulder_link"/>
    <origin xyz="0 0 0.089159" rpy="0 0 0"/>
    <axis xyz="0 0 1"/>
    <limit effort="150" lower="-3.14" upper="3.14" velocity="3.15"/>
  </joint>
  <link name="shoulder_link"/>

  <!-- Shoulder Lift Joint -->
  <joint name="shoulder_lift_joint" type="revolute">
    <parent link="shoulder_link"/>
    <child link="upper_arm_link"/>
    <origin xyz="0 0 0" rpy="0 0 0"/>
    <axis xyz="0 1 0"/>
    <limit effort="150" lower="-3.14" upper="3.14" velocity="3.15"/>
  </joint>
  <link name="upper_arm_link"/>

  <!-- Elbow Joint -->
  <joint name="elbow_joint" type="revolute">
    <parent link="upper_arm_link"/>
    <child link="forearm_link"/>
    <origin xyz="0.425 0 0" rpy="0 0 0"/>
    <axis xyz="0 1 0"/>
    <limit effort="150" lower="-3.14" upper="3.14" velocity="3.15"/>
  </joint>
  <link name="forearm_link"/>

  <!-- Wrist 1 Joint -->
  <joint name="wrist_1_joint" type="revolute">
    <parent link="forearm_link"/>
    <child link="wrist_1_link"/>
    <origin xyz="0.39225 0 0" rpy="0 0 0"/>
    <axis xyz="0 1 0"/>
    <limit effort="28" lower="-3.14" upper="3.14" velocity="3.15"/>
  </joint>
  <link name="wrist_1_link"/>

  <!-- Wrist 2 Joint -->
  <joint name="wrist_2_joint" type="revolute">
    <parent link="wrist_1_link"/>
    <child link="wrist_2_link"/>
    <origin xyz="0 0 0.10915" rpy="0 0 0"/>
    <axis xyz="1 0 0"/>
    <limit effort="28" lower="-3.14" upper="3.14" velocity="3.15"/>
  </joint>
  <link name="wrist_2_link"/>

  <!-- Wrist 3 Joint -->
  <joint name="wrist_3_joint" type="revolute">
    <parent link="wrist_2_link"/>
    <child link="wrist_3_link"/>
    <origin xyz="0 0 0.09465" rpy="0 0 0"/>
    <axis xyz="0 1 0"/>
    <limit effort="28" lower="-3.14" upper="3.14" velocity="3.15"/>
  </joint>
  <link name="wrist_3_link"/>

  <!-- Tool Fixed Joint -->
  <joint name="ee_fixed_joint" type="fixed">
    <parent link="wrist_3_link"/>
    <child link="tool0"/>
    <origin xyz="0 0 0.0823" rpy="0 0 0"/>
  </joint>
  <link name="tool0"/>

  <!-- =========================== -->
  <!--      Depth Camera Add-on    -->
  <!-- =========================== -->

  <!-- Visual Representation -->
  <link name="depth_camera_link">
    <visual>
      <geometry>
        <box size="0.04 0.04 0.04"/>
      </geometry>
      <material>
        <color rgba="0 0 1 1"/>
      </material>
    </visual>
  </link>

  <!-- Mount Camera on Wrist 3 -->
  <joint name="depth_camera_joint" type="fixed">
    <parent link="wrist_3_link"/>
    <child link="depth_camera_link"/>
    <origin xyz="0 0 0.1" rpy="0 0 0"/>
  </joint>

  <!-- Gazebo Plugin for Depth Camera -->
  <gazebo reference="depth_camera_link">
    <sensor name="depth_camera_sensor" type="depth">
      <always_on>true</always_on>
      <update_rate>30</update_rate>

      <camera>
        <horizontal_fov>1.3962634</horizontal_fov>
        <image>
          <width>640</width>
          <height>480</height>
          <format>R8G8B8</format>
        </image>
        <clip>
          <near>0.05</near>
          <far>5.0</far>
        </clip>
      </camera>

      <!-- ROS Interface Plugin -->
      <plugin name="depth_camera_controller" filename="libgazebo_ros_camera.so">
        <always_on>true</always_on>
        <update_rate>30.0</update_rate>
        <camera_name>depth_camera</camera_name>
        <image_topic_name>image_raw</image_topic_name>
        <camera_info_topic_name>camera_info</camera_info_topic_name>
        <depth_image_topic_name>depth/image_raw</depth_image_topic_name>
        <depth_info_topic_name>depth/camera_info</depth_info_topic_name>
        <frame_name>depth_camera_link</frame_name>
      </plugin>
    </sensor>
  </gazebo>

</robot>
